[2024-12-09T07:51:11.877+0000] {local_task_job_runner.py:123} INFO - ::group::Pre task execution logs
[2024-12-09T07:51:11.897+0000] {taskinstance.py:2613} INFO - Dependencies all met for dep_context=non-requeueable deps ti=<TaskInstance: dag0_test0.fetch_mongo_data manual__2024-12-09T07:46:08.773247+00:00 [queued]>
[2024-12-09T07:51:11.908+0000] {taskinstance.py:2613} INFO - Dependencies all met for dep_context=requeueable deps ti=<TaskInstance: dag0_test0.fetch_mongo_data manual__2024-12-09T07:46:08.773247+00:00 [queued]>
[2024-12-09T07:51:11.909+0000] {taskinstance.py:2866} INFO - Starting attempt 2 of 2
[2024-12-09T07:51:11.925+0000] {taskinstance.py:2889} INFO - Executing <Task(PythonOperator): fetch_mongo_data> on 2024-12-09 07:46:08.773247+00:00
[2024-12-09T07:51:11.931+0000] {warnings.py:112} WARNING - /home/***/.local/lib/python3.12/site-packages/***/task/task_runner/standard_task_runner.py:70: DeprecationWarning: This process (pid=271) is multi-threaded, use of fork() may lead to deadlocks in the child.
  pid = os.fork()

[2024-12-09T07:51:11.932+0000] {standard_task_runner.py:72} INFO - Started process 272 to run task
[2024-12-09T07:51:11.933+0000] {standard_task_runner.py:104} INFO - Running: ['***', 'tasks', 'run', 'dag0_test0', 'fetch_mongo_data', 'manual__2024-12-09T07:46:08.773247+00:00', '--job-id', '14', '--raw', '--subdir', 'DAGS_FOLDER/dag0.py', '--cfg-path', '/tmp/tmpr6n99gav']
[2024-12-09T07:51:11.934+0000] {standard_task_runner.py:105} INFO - Job 14: Subtask fetch_mongo_data
[2024-12-09T07:51:11.988+0000] {task_command.py:467} INFO - Running <TaskInstance: dag0_test0.fetch_mongo_data manual__2024-12-09T07:46:08.773247+00:00 [running]> on host c23cf8b5bd6f
[2024-12-09T07:51:12.088+0000] {taskinstance.py:3132} INFO - Exporting env vars: AIRFLOW_CTX_DAG_OWNER='***' AIRFLOW_CTX_DAG_ID='dag0_test0' AIRFLOW_CTX_TASK_ID='fetch_mongo_data' AIRFLOW_CTX_EXECUTION_DATE='2024-12-09T07:46:08.773247+00:00' AIRFLOW_CTX_TRY_NUMBER='2' AIRFLOW_CTX_DAG_RUN_ID='manual__2024-12-09T07:46:08.773247+00:00'
[2024-12-09T07:51:12.090+0000] {taskinstance.py:731} INFO - ::endgroup::
[2024-12-09T07:51:12.108+0000] {logging_mixin.py:190} INFO - hell
[2024-12-09T07:51:12.139+0000] {taskinstance.py:3311} ERROR - Task failed with exception
Traceback (most recent call last):
  File "/home/airflow/.local/lib/python3.12/site-packages/airflow/models/taskinstance.py", line 767, in _execute_task
    result = _execute_callable(context=context, **execute_callable_kwargs)
             ^^^^^^^^^^^^^^^^^^^^^^^^^^^^^^^^^^^^^^^^^^^^^^^^^^^^^^^^^^^^^
  File "/home/airflow/.local/lib/python3.12/site-packages/airflow/models/taskinstance.py", line 733, in _execute_callable
    return ExecutionCallableRunner(
           ^^^^^^^^^^^^^^^^^^^^^^^^
  File "/home/airflow/.local/lib/python3.12/site-packages/airflow/utils/operator_helpers.py", line 252, in run
    return self.func(*args, **kwargs)
           ^^^^^^^^^^^^^^^^^^^^^^^^^^
  File "/home/airflow/.local/lib/python3.12/site-packages/airflow/models/baseoperator.py", line 417, in wrapper
    return func(self, *args, **kwargs)
           ^^^^^^^^^^^^^^^^^^^^^^^^^^^
  File "/home/airflow/.local/lib/python3.12/site-packages/airflow/operators/python.py", line 238, in execute
    return_value = self.execute_callable()
                   ^^^^^^^^^^^^^^^^^^^^^^^
  File "/home/airflow/.local/lib/python3.12/site-packages/airflow/operators/python.py", line 256, in execute_callable
    return runner.run(*self.op_args, **self.op_kwargs)
           ^^^^^^^^^^^^^^^^^^^^^^^^^^^^^^^^^^^^^^^^^^^
  File "/home/airflow/.local/lib/python3.12/site-packages/airflow/utils/operator_helpers.py", line 252, in run
    return self.func(*args, **kwargs)
           ^^^^^^^^^^^^^^^^^^^^^^^^^^
  File "/opt/airflow/dags/dag0.py", line 33, in fetch_data_from_mongo
    from settings import settings
  File "/opt/airflow/dags/settings.py", line 13, in <module>
    settings = Settings()
               ^^^^^^^^^^
  File "/home/airflow/.local/lib/python3.12/site-packages/pydantic_settings/main.py", line 167, in __init__
    super().__init__(
  File "/home/airflow/.local/lib/python3.12/site-packages/pydantic/main.py", line 212, in __init__
    validated_self = self.__pydantic_validator__.validate_python(data, self_instance=self)
                     ^^^^^^^^^^^^^^^^^^^^^^^^^^^^^^^^^^^^^^^^^^^^^^^^^^^^^^^^^^^^^^^^^^^^^
pydantic_core._pydantic_core.ValidationError: 1 validation error for Settings
mongo_url
  Field required [type=missing, input_value={}, input_type=dict]
    For further information visit https://errors.pydantic.dev/2.9/v/missing
[2024-12-09T07:51:12.160+0000] {taskinstance.py:1225} INFO - Marking task as FAILED. dag_id=dag0_test0, task_id=fetch_mongo_data, run_id=manual__2024-12-09T07:46:08.773247+00:00, execution_date=20241209T074608, start_date=20241209T075111, end_date=20241209T075112
[2024-12-09T07:51:12.173+0000] {taskinstance.py:340} INFO - ::group::Post task execution logs
[2024-12-09T07:51:12.174+0000] {standard_task_runner.py:124} ERROR - Failed to execute job 14 for task fetch_mongo_data (1 validation error for Settings
mongo_url
  Field required [type=missing, input_value={}, input_type=dict]
    For further information visit https://errors.pydantic.dev/2.9/v/missing; 272)
Traceback (most recent call last):
  File "/home/airflow/.local/lib/python3.12/site-packages/airflow/task/task_runner/standard_task_runner.py", line 117, in _start_by_fork
    ret = args.func(args, dag=self.dag)
          ^^^^^^^^^^^^^^^^^^^^^^^^^^^^^
  File "/home/airflow/.local/lib/python3.12/site-packages/airflow/cli/cli_config.py", line 49, in command
    return func(*args, **kwargs)
           ^^^^^^^^^^^^^^^^^^^^^
  File "/home/airflow/.local/lib/python3.12/site-packages/airflow/utils/cli.py", line 116, in wrapper
    return f(*args, **kwargs)
           ^^^^^^^^^^^^^^^^^^
  File "/home/airflow/.local/lib/python3.12/site-packages/airflow/cli/commands/task_command.py", line 483, in task_run
    task_return_code = _run_task_by_selected_method(args, _dag, ti)
                       ^^^^^^^^^^^^^^^^^^^^^^^^^^^^^^^^^^^^^^^^^^^^
  File "/home/airflow/.local/lib/python3.12/site-packages/airflow/cli/commands/task_command.py", line 256, in _run_task_by_selected_method
    return _run_raw_task(args, ti)
           ^^^^^^^^^^^^^^^^^^^^^^^
  File "/home/airflow/.local/lib/python3.12/site-packages/airflow/cli/commands/task_command.py", line 341, in _run_raw_task
    return ti._run_raw_task(
           ^^^^^^^^^^^^^^^^^
  File "/home/airflow/.local/lib/python3.12/site-packages/airflow/utils/session.py", line 97, in wrapper
    return func(*args, session=session, **kwargs)
           ^^^^^^^^^^^^^^^^^^^^^^^^^^^^^^^^^^^^^^
  File "/home/airflow/.local/lib/python3.12/site-packages/airflow/models/taskinstance.py", line 3005, in _run_raw_task
    return _run_raw_task(
           ^^^^^^^^^^^^^^
  File "/home/airflow/.local/lib/python3.12/site-packages/airflow/models/taskinstance.py", line 273, in _run_raw_task
    TaskInstance._execute_task_with_callbacks(
  File "/home/airflow/.local/lib/python3.12/site-packages/airflow/models/taskinstance.py", line 3159, in _execute_task_with_callbacks
    result = self._execute_task(context, task_orig)
             ^^^^^^^^^^^^^^^^^^^^^^^^^^^^^^^^^^^^^^
  File "/home/airflow/.local/lib/python3.12/site-packages/airflow/models/taskinstance.py", line 3183, in _execute_task
    return _execute_task(self, context, task_orig)
           ^^^^^^^^^^^^^^^^^^^^^^^^^^^^^^^^^^^^^^^
  File "/home/airflow/.local/lib/python3.12/site-packages/airflow/models/taskinstance.py", line 767, in _execute_task
    result = _execute_callable(context=context, **execute_callable_kwargs)
             ^^^^^^^^^^^^^^^^^^^^^^^^^^^^^^^^^^^^^^^^^^^^^^^^^^^^^^^^^^^^^
  File "/home/airflow/.local/lib/python3.12/site-packages/airflow/models/taskinstance.py", line 733, in _execute_callable
    return ExecutionCallableRunner(
           ^^^^^^^^^^^^^^^^^^^^^^^^
  File "/home/airflow/.local/lib/python3.12/site-packages/airflow/utils/operator_helpers.py", line 252, in run
    return self.func(*args, **kwargs)
           ^^^^^^^^^^^^^^^^^^^^^^^^^^
  File "/home/airflow/.local/lib/python3.12/site-packages/airflow/models/baseoperator.py", line 417, in wrapper
    return func(self, *args, **kwargs)
           ^^^^^^^^^^^^^^^^^^^^^^^^^^^
  File "/home/airflow/.local/lib/python3.12/site-packages/airflow/operators/python.py", line 238, in execute
    return_value = self.execute_callable()
                   ^^^^^^^^^^^^^^^^^^^^^^^
  File "/home/airflow/.local/lib/python3.12/site-packages/airflow/operators/python.py", line 256, in execute_callable
    return runner.run(*self.op_args, **self.op_kwargs)
           ^^^^^^^^^^^^^^^^^^^^^^^^^^^^^^^^^^^^^^^^^^^
  File "/home/airflow/.local/lib/python3.12/site-packages/airflow/utils/operator_helpers.py", line 252, in run
    return self.func(*args, **kwargs)
           ^^^^^^^^^^^^^^^^^^^^^^^^^^
  File "/opt/airflow/dags/dag0.py", line 33, in fetch_data_from_mongo
    from settings import settings
  File "/opt/airflow/dags/settings.py", line 13, in <module>
    settings = Settings()
               ^^^^^^^^^^
  File "/home/airflow/.local/lib/python3.12/site-packages/pydantic_settings/main.py", line 167, in __init__
    super().__init__(
  File "/home/airflow/.local/lib/python3.12/site-packages/pydantic/main.py", line 212, in __init__
    validated_self = self.__pydantic_validator__.validate_python(data, self_instance=self)
                     ^^^^^^^^^^^^^^^^^^^^^^^^^^^^^^^^^^^^^^^^^^^^^^^^^^^^^^^^^^^^^^^^^^^^^
pydantic_core._pydantic_core.ValidationError: 1 validation error for Settings
mongo_url
  Field required [type=missing, input_value={}, input_type=dict]
    For further information visit https://errors.pydantic.dev/2.9/v/missing
[2024-12-09T07:51:12.188+0000] {local_task_job_runner.py:266} INFO - Task exited with return code 1
[2024-12-09T07:51:12.207+0000] {taskinstance.py:3895} INFO - 0 downstream tasks scheduled from follow-on schedule check
[2024-12-09T07:51:12.209+0000] {local_task_job_runner.py:245} INFO - ::endgroup::
