[2024-12-06T12:52:32.003+0000] {local_task_job_runner.py:123} INFO - ::group::Pre task execution logs
[2024-12-06T12:52:32.047+0000] {taskinstance.py:2613} INFO - Dependencies all met for dep_context=non-requeueable deps ti=<TaskInstance: dag_to_s3.load_to_s3 scheduled__2024-12-04T15:00:00+00:00 [queued]>
[2024-12-06T12:52:32.075+0000] {taskinstance.py:2613} INFO - Dependencies all met for dep_context=requeueable deps ti=<TaskInstance: dag_to_s3.load_to_s3 scheduled__2024-12-04T15:00:00+00:00 [queued]>
[2024-12-06T12:52:32.076+0000] {taskinstance.py:2866} INFO - Starting attempt 1 of 1
[2024-12-06T12:52:32.109+0000] {taskinstance.py:2889} INFO - Executing <Task(PythonOperator): load_to_s3> on 2024-12-04 15:00:00+00:00
[2024-12-06T12:52:32.120+0000] {warnings.py:112} WARNING - /home/***/.local/lib/python3.12/site-packages/***/task/task_runner/standard_task_runner.py:70: DeprecationWarning: This process (pid=726) is multi-threaded, use of fork() may lead to deadlocks in the child.
  pid = os.fork()

[2024-12-06T12:52:32.123+0000] {standard_task_runner.py:72} INFO - Started process 729 to run task
[2024-12-06T12:52:32.126+0000] {standard_task_runner.py:104} INFO - Running: ['***', 'tasks', 'run', 'dag_to_s3', 'load_to_s3', 'scheduled__2024-12-04T15:00:00+00:00', '--job-id', '445', '--raw', '--subdir', 'DAGS_FOLDER/tests3.py', '--cfg-path', '/tmp/tmpcli5up0g']
[2024-12-06T12:52:32.132+0000] {standard_task_runner.py:105} INFO - Job 445: Subtask load_to_s3
[2024-12-06T12:52:32.240+0000] {task_command.py:467} INFO - Running <TaskInstance: dag_to_s3.load_to_s3 scheduled__2024-12-04T15:00:00+00:00 [running]> on host bc436253e42c
[2024-12-06T12:52:32.434+0000] {taskinstance.py:3132} INFO - Exporting env vars: AIRFLOW_CTX_DAG_OWNER='ANN' AIRFLOW_CTX_DAG_ID='dag_to_s3' AIRFLOW_CTX_TASK_ID='load_to_s3' AIRFLOW_CTX_EXECUTION_DATE='2024-12-04T15:00:00+00:00' AIRFLOW_CTX_TRY_NUMBER='1' AIRFLOW_CTX_DAG_RUN_ID='scheduled__2024-12-04T15:00:00+00:00'
[2024-12-06T12:52:32.437+0000] {taskinstance.py:731} INFO - ::endgroup::
[2024-12-06T12:52:33.281+0000] {logging_mixin.py:190} INFO - gjlasdfghjkl;
[2024-12-06T12:52:33.282+0000] {taskinstance.py:3311} ERROR - Task failed with exception
Traceback (most recent call last):
  File "/home/airflow/.local/lib/python3.12/site-packages/airflow/models/taskinstance.py", line 767, in _execute_task
    result = _execute_callable(context=context, **execute_callable_kwargs)
             ^^^^^^^^^^^^^^^^^^^^^^^^^^^^^^^^^^^^^^^^^^^^^^^^^^^^^^^^^^^^^
  File "/home/airflow/.local/lib/python3.12/site-packages/airflow/models/taskinstance.py", line 733, in _execute_callable
    return ExecutionCallableRunner(
           ^^^^^^^^^^^^^^^^^^^^^^^^
  File "/home/airflow/.local/lib/python3.12/site-packages/airflow/utils/operator_helpers.py", line 252, in run
    return self.func(*args, **kwargs)
           ^^^^^^^^^^^^^^^^^^^^^^^^^^
  File "/home/airflow/.local/lib/python3.12/site-packages/airflow/models/baseoperator.py", line 417, in wrapper
    return func(self, *args, **kwargs)
           ^^^^^^^^^^^^^^^^^^^^^^^^^^^
  File "/home/airflow/.local/lib/python3.12/site-packages/airflow/operators/python.py", line 238, in execute
    return_value = self.execute_callable()
                   ^^^^^^^^^^^^^^^^^^^^^^^
  File "/home/airflow/.local/lib/python3.12/site-packages/airflow/operators/python.py", line 256, in execute_callable
    return runner.run(*self.op_args, **self.op_kwargs)
           ^^^^^^^^^^^^^^^^^^^^^^^^^^^^^^^^^^^^^^^^^^^
  File "/home/airflow/.local/lib/python3.12/site-packages/airflow/utils/operator_helpers.py", line 252, in run
    return self.func(*args, **kwargs)
           ^^^^^^^^^^^^^^^^^^^^^^^^^^
  File "/opt/airflow/dags/tests3.py", line 60, in to_s3
    for json_doc in new_data:
                    ^^^^^^^^
NameError: name 'new_data' is not defined
[2024-12-06T12:52:33.320+0000] {taskinstance.py:1225} INFO - Marking task as FAILED. dag_id=dag_to_s3, task_id=load_to_s3, run_id=scheduled__2024-12-04T15:00:00+00:00, execution_date=20241204T150000, start_date=20241206T125232, end_date=20241206T125233
[2024-12-06T12:52:33.345+0000] {taskinstance.py:340} INFO - ::group::Post task execution logs
[2024-12-06T12:52:33.346+0000] {standard_task_runner.py:124} ERROR - Failed to execute job 445 for task load_to_s3 (name 'new_data' is not defined; 729)
Traceback (most recent call last):
  File "/home/airflow/.local/lib/python3.12/site-packages/airflow/task/task_runner/standard_task_runner.py", line 117, in _start_by_fork
    ret = args.func(args, dag=self.dag)
          ^^^^^^^^^^^^^^^^^^^^^^^^^^^^^
  File "/home/airflow/.local/lib/python3.12/site-packages/airflow/cli/cli_config.py", line 49, in command
    return func(*args, **kwargs)
           ^^^^^^^^^^^^^^^^^^^^^
  File "/home/airflow/.local/lib/python3.12/site-packages/airflow/utils/cli.py", line 116, in wrapper
    return f(*args, **kwargs)
           ^^^^^^^^^^^^^^^^^^
  File "/home/airflow/.local/lib/python3.12/site-packages/airflow/cli/commands/task_command.py", line 483, in task_run
    task_return_code = _run_task_by_selected_method(args, _dag, ti)
                       ^^^^^^^^^^^^^^^^^^^^^^^^^^^^^^^^^^^^^^^^^^^^
  File "/home/airflow/.local/lib/python3.12/site-packages/airflow/cli/commands/task_command.py", line 256, in _run_task_by_selected_method
    return _run_raw_task(args, ti)
           ^^^^^^^^^^^^^^^^^^^^^^^
  File "/home/airflow/.local/lib/python3.12/site-packages/airflow/cli/commands/task_command.py", line 341, in _run_raw_task
    return ti._run_raw_task(
           ^^^^^^^^^^^^^^^^^
  File "/home/airflow/.local/lib/python3.12/site-packages/airflow/utils/session.py", line 97, in wrapper
    return func(*args, session=session, **kwargs)
           ^^^^^^^^^^^^^^^^^^^^^^^^^^^^^^^^^^^^^^
  File "/home/airflow/.local/lib/python3.12/site-packages/airflow/models/taskinstance.py", line 3005, in _run_raw_task
    return _run_raw_task(
           ^^^^^^^^^^^^^^
  File "/home/airflow/.local/lib/python3.12/site-packages/airflow/models/taskinstance.py", line 273, in _run_raw_task
    TaskInstance._execute_task_with_callbacks(
  File "/home/airflow/.local/lib/python3.12/site-packages/airflow/models/taskinstance.py", line 3159, in _execute_task_with_callbacks
    result = self._execute_task(context, task_orig)
             ^^^^^^^^^^^^^^^^^^^^^^^^^^^^^^^^^^^^^^
  File "/home/airflow/.local/lib/python3.12/site-packages/airflow/models/taskinstance.py", line 3183, in _execute_task
    return _execute_task(self, context, task_orig)
           ^^^^^^^^^^^^^^^^^^^^^^^^^^^^^^^^^^^^^^^
  File "/home/airflow/.local/lib/python3.12/site-packages/airflow/models/taskinstance.py", line 767, in _execute_task
    result = _execute_callable(context=context, **execute_callable_kwargs)
             ^^^^^^^^^^^^^^^^^^^^^^^^^^^^^^^^^^^^^^^^^^^^^^^^^^^^^^^^^^^^^
  File "/home/airflow/.local/lib/python3.12/site-packages/airflow/models/taskinstance.py", line 733, in _execute_callable
    return ExecutionCallableRunner(
           ^^^^^^^^^^^^^^^^^^^^^^^^
  File "/home/airflow/.local/lib/python3.12/site-packages/airflow/utils/operator_helpers.py", line 252, in run
    return self.func(*args, **kwargs)
           ^^^^^^^^^^^^^^^^^^^^^^^^^^
  File "/home/airflow/.local/lib/python3.12/site-packages/airflow/models/baseoperator.py", line 417, in wrapper
    return func(self, *args, **kwargs)
           ^^^^^^^^^^^^^^^^^^^^^^^^^^^
  File "/home/airflow/.local/lib/python3.12/site-packages/airflow/operators/python.py", line 238, in execute
    return_value = self.execute_callable()
                   ^^^^^^^^^^^^^^^^^^^^^^^
  File "/home/airflow/.local/lib/python3.12/site-packages/airflow/operators/python.py", line 256, in execute_callable
    return runner.run(*self.op_args, **self.op_kwargs)
           ^^^^^^^^^^^^^^^^^^^^^^^^^^^^^^^^^^^^^^^^^^^
  File "/home/airflow/.local/lib/python3.12/site-packages/airflow/utils/operator_helpers.py", line 252, in run
    return self.func(*args, **kwargs)
           ^^^^^^^^^^^^^^^^^^^^^^^^^^
  File "/opt/airflow/dags/tests3.py", line 60, in to_s3
    for json_doc in new_data:
                    ^^^^^^^^
NameError: name 'new_data' is not defined
[2024-12-06T12:52:33.386+0000] {local_task_job_runner.py:266} INFO - Task exited with return code 1
[2024-12-06T12:52:33.410+0000] {taskinstance.py:3895} INFO - 0 downstream tasks scheduled from follow-on schedule check
[2024-12-06T12:52:33.412+0000] {local_task_job_runner.py:245} INFO - ::endgroup::
