[2024-12-03T19:23:58.407+0000] {local_task_job_runner.py:123} INFO - ::group::Pre task execution logs
[2024-12-03T19:23:58.425+0000] {taskinstance.py:2613} INFO - Dependencies all met for dep_context=non-requeueable deps ti=<TaskInstance: mongo_to_kafka.send_to_kafka manual__2024-12-03T19:23:53.144188+00:00 [queued]>
[2024-12-03T19:23:58.435+0000] {taskinstance.py:2613} INFO - Dependencies all met for dep_context=requeueable deps ti=<TaskInstance: mongo_to_kafka.send_to_kafka manual__2024-12-03T19:23:53.144188+00:00 [queued]>
[2024-12-03T19:23:58.436+0000] {taskinstance.py:2866} INFO - Starting attempt 1 of 2
[2024-12-03T19:23:58.451+0000] {taskinstance.py:2889} INFO - Executing <Task(PythonOperator): send_to_kafka> on 2024-12-03 19:23:53.144188+00:00
[2024-12-03T19:23:58.455+0000] {warnings.py:112} WARNING - /home/***/.local/lib/python3.12/site-packages/***/task/task_runner/standard_task_runner.py:70: DeprecationWarning: This process (pid=300) is multi-threaded, use of fork() may lead to deadlocks in the child.
  pid = os.fork()

[2024-12-03T19:23:58.457+0000] {standard_task_runner.py:72} INFO - Started process 301 to run task
[2024-12-03T19:23:58.458+0000] {standard_task_runner.py:104} INFO - Running: ['***', 'tasks', 'run', 'mongo_to_kafka', 'send_to_kafka', 'manual__2024-12-03T19:23:53.144188+00:00', '--job-id', '104', '--raw', '--subdir', 'DAGS_FOLDER/dag1_MongoKafka.py', '--cfg-path', '/tmp/tmp2x0k0g6t']
[2024-12-03T19:23:58.460+0000] {standard_task_runner.py:105} INFO - Job 104: Subtask send_to_kafka
[2024-12-03T19:23:58.504+0000] {task_command.py:467} INFO - Running <TaskInstance: mongo_to_kafka.send_to_kafka manual__2024-12-03T19:23:53.144188+00:00 [running]> on host 31ac0cc6adcb
[2024-12-03T19:23:58.589+0000] {taskinstance.py:3132} INFO - Exporting env vars: AIRFLOW_CTX_DAG_OWNER='***' AIRFLOW_CTX_DAG_ID='mongo_to_kafka' AIRFLOW_CTX_TASK_ID='send_to_kafka' AIRFLOW_CTX_EXECUTION_DATE='2024-12-03T19:23:53.144188+00:00' AIRFLOW_CTX_TRY_NUMBER='1' AIRFLOW_CTX_DAG_RUN_ID='manual__2024-12-03T19:23:53.144188+00:00'
[2024-12-03T19:23:58.591+0000] {taskinstance.py:731} INFO - ::endgroup::
[2024-12-03T19:23:58.963+0000] {logging_mixin.py:190} INFO - {"_id": "6707fa42840c437097f7b593", "travel": 3, "payer": 1, "amount": 26092, "code_departure": "SIN", "code_arrival": "ICN", "number_of_passengers": 4, "passengers": [{"passenger": "Zoe Barnaby", "birth_date": "1993-09-24"}, {"name": "Ružica Ivančević", "birth_date": "1995-09-02"}, {"name": "Timm Raabe", "birth_date": "1976-11-19"}, {"name": "Greta Oorschot", "birth_date": "1993-08-19"}], "created": "2024-10-10T16:01:06.102000"}
[2024-12-03T19:23:58.964+0000] {logging_mixin.py:190} INFO - {'_id': '6707fa42840c437097f7b593', 'travel': 3, 'payer': 1, 'amount': 26092, 'code_departure': 'SIN', 'code_arrival': 'ICN', 'number_of_passengers': 4, 'passengers': [{'passenger': 'Zoe Barnaby', 'birth_date': '1993-09-24'}, {'name': 'Ružica Ivančević', 'birth_date': '1995-09-02'}, {'name': 'Timm Raabe', 'birth_date': '1976-11-19'}, {'name': 'Greta Oorschot', 'birth_date': '1993-08-19'}], 'created': '2024-10-10T16:01:06.102000'}
[2024-12-03T19:23:59.149+0000] {taskinstance.py:3311} ERROR - Task failed with exception
Traceback (most recent call last):
  File "/home/airflow/.local/lib/python3.12/site-packages/airflow/models/taskinstance.py", line 767, in _execute_task
    result = _execute_callable(context=context, **execute_callable_kwargs)
             ^^^^^^^^^^^^^^^^^^^^^^^^^^^^^^^^^^^^^^^^^^^^^^^^^^^^^^^^^^^^^
  File "/home/airflow/.local/lib/python3.12/site-packages/airflow/models/taskinstance.py", line 733, in _execute_callable
    return ExecutionCallableRunner(
           ^^^^^^^^^^^^^^^^^^^^^^^^
  File "/home/airflow/.local/lib/python3.12/site-packages/airflow/utils/operator_helpers.py", line 252, in run
    return self.func(*args, **kwargs)
           ^^^^^^^^^^^^^^^^^^^^^^^^^^
  File "/home/airflow/.local/lib/python3.12/site-packages/airflow/models/baseoperator.py", line 417, in wrapper
    return func(self, *args, **kwargs)
           ^^^^^^^^^^^^^^^^^^^^^^^^^^^
  File "/home/airflow/.local/lib/python3.12/site-packages/airflow/operators/python.py", line 238, in execute
    return_value = self.execute_callable()
                   ^^^^^^^^^^^^^^^^^^^^^^^
  File "/home/airflow/.local/lib/python3.12/site-packages/airflow/operators/python.py", line 256, in execute_callable
    return runner.run(*self.op_args, **self.op_kwargs)
           ^^^^^^^^^^^^^^^^^^^^^^^^^^^^^^^^^^^^^^^^^^^
  File "/home/airflow/.local/lib/python3.12/site-packages/airflow/utils/operator_helpers.py", line 252, in run
    return self.func(*args, **kwargs)
           ^^^^^^^^^^^^^^^^^^^^^^^^^^
  File "/opt/airflow/dags/dag1_MongoKafka.py", line 144, in send_data_to_kafka
    value=avro_serializer(
          ^^^^^^^^^^^^^^^^
  File "/home/airflow/.local/lib/python3.12/site-packages/confluent_kafka/schema_registry/avro.py", line 308, in __call__
    schemaless_writer(fo, self._parsed_schema, value)
  File "fastavro/_write.pyx", line 811, in fastavro._write.schemaless_writer
  File "fastavro/_write.pyx", line 465, in fastavro._write.write_data
  File "fastavro/_write.pyx", line 409, in fastavro._write.write_record
  File "fastavro/_write.pyx", line 459, in fastavro._write.write_data
  File "fastavro/_write.pyx", line 181, in fastavro._write.write_array
  File "fastavro/_write.pyx", line 465, in fastavro._write.write_data
  File "fastavro/_write.pyx", line 404, in fastavro._write.write_record
ValueError: no value and no default for name
[2024-12-03T19:23:59.168+0000] {taskinstance.py:1225} INFO - Marking task as UP_FOR_RETRY. dag_id=mongo_to_kafka, task_id=send_to_kafka, run_id=manual__2024-12-03T19:23:53.144188+00:00, execution_date=20241203T192353, start_date=20241203T192358, end_date=20241203T192359
[2024-12-03T19:23:59.188+0000] {taskinstance.py:340} INFO - ::group::Post task execution logs
[2024-12-03T19:23:59.189+0000] {standard_task_runner.py:124} ERROR - Failed to execute job 104 for task send_to_kafka (no value and no default for name; 301)
Traceback (most recent call last):
  File "/home/airflow/.local/lib/python3.12/site-packages/airflow/task/task_runner/standard_task_runner.py", line 117, in _start_by_fork
    ret = args.func(args, dag=self.dag)
          ^^^^^^^^^^^^^^^^^^^^^^^^^^^^^
  File "/home/airflow/.local/lib/python3.12/site-packages/airflow/cli/cli_config.py", line 49, in command
    return func(*args, **kwargs)
           ^^^^^^^^^^^^^^^^^^^^^
  File "/home/airflow/.local/lib/python3.12/site-packages/airflow/utils/cli.py", line 116, in wrapper
    return f(*args, **kwargs)
           ^^^^^^^^^^^^^^^^^^
  File "/home/airflow/.local/lib/python3.12/site-packages/airflow/cli/commands/task_command.py", line 483, in task_run
    task_return_code = _run_task_by_selected_method(args, _dag, ti)
                       ^^^^^^^^^^^^^^^^^^^^^^^^^^^^^^^^^^^^^^^^^^^^
  File "/home/airflow/.local/lib/python3.12/site-packages/airflow/cli/commands/task_command.py", line 256, in _run_task_by_selected_method
    return _run_raw_task(args, ti)
           ^^^^^^^^^^^^^^^^^^^^^^^
  File "/home/airflow/.local/lib/python3.12/site-packages/airflow/cli/commands/task_command.py", line 341, in _run_raw_task
    return ti._run_raw_task(
           ^^^^^^^^^^^^^^^^^
  File "/home/airflow/.local/lib/python3.12/site-packages/airflow/utils/session.py", line 97, in wrapper
    return func(*args, session=session, **kwargs)
           ^^^^^^^^^^^^^^^^^^^^^^^^^^^^^^^^^^^^^^
  File "/home/airflow/.local/lib/python3.12/site-packages/airflow/models/taskinstance.py", line 3005, in _run_raw_task
    return _run_raw_task(
           ^^^^^^^^^^^^^^
  File "/home/airflow/.local/lib/python3.12/site-packages/airflow/models/taskinstance.py", line 273, in _run_raw_task
    TaskInstance._execute_task_with_callbacks(
  File "/home/airflow/.local/lib/python3.12/site-packages/airflow/models/taskinstance.py", line 3159, in _execute_task_with_callbacks
    result = self._execute_task(context, task_orig)
             ^^^^^^^^^^^^^^^^^^^^^^^^^^^^^^^^^^^^^^
  File "/home/airflow/.local/lib/python3.12/site-packages/airflow/models/taskinstance.py", line 3183, in _execute_task
    return _execute_task(self, context, task_orig)
           ^^^^^^^^^^^^^^^^^^^^^^^^^^^^^^^^^^^^^^^
  File "/home/airflow/.local/lib/python3.12/site-packages/airflow/models/taskinstance.py", line 767, in _execute_task
    result = _execute_callable(context=context, **execute_callable_kwargs)
             ^^^^^^^^^^^^^^^^^^^^^^^^^^^^^^^^^^^^^^^^^^^^^^^^^^^^^^^^^^^^^
  File "/home/airflow/.local/lib/python3.12/site-packages/airflow/models/taskinstance.py", line 733, in _execute_callable
    return ExecutionCallableRunner(
           ^^^^^^^^^^^^^^^^^^^^^^^^
  File "/home/airflow/.local/lib/python3.12/site-packages/airflow/utils/operator_helpers.py", line 252, in run
    return self.func(*args, **kwargs)
           ^^^^^^^^^^^^^^^^^^^^^^^^^^
  File "/home/airflow/.local/lib/python3.12/site-packages/airflow/models/baseoperator.py", line 417, in wrapper
    return func(self, *args, **kwargs)
           ^^^^^^^^^^^^^^^^^^^^^^^^^^^
  File "/home/airflow/.local/lib/python3.12/site-packages/airflow/operators/python.py", line 238, in execute
    return_value = self.execute_callable()
                   ^^^^^^^^^^^^^^^^^^^^^^^
  File "/home/airflow/.local/lib/python3.12/site-packages/airflow/operators/python.py", line 256, in execute_callable
    return runner.run(*self.op_args, **self.op_kwargs)
           ^^^^^^^^^^^^^^^^^^^^^^^^^^^^^^^^^^^^^^^^^^^
  File "/home/airflow/.local/lib/python3.12/site-packages/airflow/utils/operator_helpers.py", line 252, in run
    return self.func(*args, **kwargs)
           ^^^^^^^^^^^^^^^^^^^^^^^^^^
  File "/opt/airflow/dags/dag1_MongoKafka.py", line 144, in send_data_to_kafka
    value=avro_serializer(
          ^^^^^^^^^^^^^^^^
  File "/home/airflow/.local/lib/python3.12/site-packages/confluent_kafka/schema_registry/avro.py", line 308, in __call__
    schemaless_writer(fo, self._parsed_schema, value)
  File "fastavro/_write.pyx", line 811, in fastavro._write.schemaless_writer
  File "fastavro/_write.pyx", line 465, in fastavro._write.write_data
  File "fastavro/_write.pyx", line 409, in fastavro._write.write_record
  File "fastavro/_write.pyx", line 459, in fastavro._write.write_data
  File "fastavro/_write.pyx", line 181, in fastavro._write.write_array
  File "fastavro/_write.pyx", line 465, in fastavro._write.write_data
  File "fastavro/_write.pyx", line 404, in fastavro._write.write_record
ValueError: no value and no default for name
[2024-12-03T19:23:59.235+0000] {local_task_job_runner.py:266} INFO - Task exited with return code 1
[2024-12-03T19:23:59.258+0000] {taskinstance.py:3895} INFO - 0 downstream tasks scheduled from follow-on schedule check
[2024-12-03T19:23:59.260+0000] {local_task_job_runner.py:245} INFO - ::endgroup::
