[2024-12-05T06:40:55.869+0000] {local_task_job_runner.py:123} INFO - ::group::Pre task execution logs
[2024-12-05T06:40:55.887+0000] {taskinstance.py:2613} INFO - Dependencies all met for dep_context=non-requeueable deps ti=<TaskInstance: kafka_read.consume_from_topic scheduled__2024-12-04T00:00:00+00:00 [queued]>
[2024-12-05T06:40:55.898+0000] {taskinstance.py:2613} INFO - Dependencies all met for dep_context=requeueable deps ti=<TaskInstance: kafka_read.consume_from_topic scheduled__2024-12-04T00:00:00+00:00 [queued]>
[2024-12-05T06:40:55.899+0000] {taskinstance.py:2866} INFO - Starting attempt 2 of 2
[2024-12-05T06:40:55.915+0000] {taskinstance.py:2889} INFO - Executing <Task(ConsumeFromTopicOperator): consume_from_topic> on 2024-12-04 00:00:00+00:00
[2024-12-05T06:40:55.920+0000] {warnings.py:112} WARNING - /home/***/.local/lib/python3.12/site-packages/***/task/task_runner/standard_task_runner.py:70: DeprecationWarning: This process (pid=154) is multi-threaded, use of fork() may lead to deadlocks in the child.
  pid = os.fork()

[2024-12-05T06:40:55.922+0000] {standard_task_runner.py:72} INFO - Started process 155 to run task
[2024-12-05T06:40:55.922+0000] {standard_task_runner.py:104} INFO - Running: ['***', 'tasks', 'run', 'kafka_read', 'consume_from_topic', 'scheduled__2024-12-04T00:00:00+00:00', '--job-id', '325', '--raw', '--subdir', 'DAGS_FOLDER/dag2_Kafkas3.py', '--cfg-path', '/tmp/tmpk39c_h_8']
[2024-12-05T06:40:55.925+0000] {standard_task_runner.py:105} INFO - Job 325: Subtask consume_from_topic
[2024-12-05T06:40:55.973+0000] {task_command.py:467} INFO - Running <TaskInstance: kafka_read.consume_from_topic scheduled__2024-12-04T00:00:00+00:00 [running]> on host bc436253e42c
[2024-12-05T06:40:56.070+0000] {taskinstance.py:3132} INFO - Exporting env vars: AIRFLOW_CTX_DAG_OWNER='***' AIRFLOW_CTX_DAG_ID='kafka_read' AIRFLOW_CTX_TASK_ID='consume_from_topic' AIRFLOW_CTX_EXECUTION_DATE='2024-12-04T00:00:00+00:00' AIRFLOW_CTX_TRY_NUMBER='2' AIRFLOW_CTX_DAG_RUN_ID='scheduled__2024-12-04T00:00:00+00:00'
[2024-12-05T06:40:56.071+0000] {taskinstance.py:731} INFO - ::endgroup::
[2024-12-05T06:40:56.100+0000] {taskinstance.py:3311} ERROR - Task failed with exception
Traceback (most recent call last):
  File "/home/airflow/.local/lib/python3.12/site-packages/airflow/models/taskinstance.py", line 767, in _execute_task
    result = _execute_callable(context=context, **execute_callable_kwargs)
             ^^^^^^^^^^^^^^^^^^^^^^^^^^^^^^^^^^^^^^^^^^^^^^^^^^^^^^^^^^^^^
  File "/home/airflow/.local/lib/python3.12/site-packages/airflow/models/taskinstance.py", line 733, in _execute_callable
    return ExecutionCallableRunner(
           ^^^^^^^^^^^^^^^^^^^^^^^^
  File "/home/airflow/.local/lib/python3.12/site-packages/airflow/utils/operator_helpers.py", line 252, in run
    return self.func(*args, **kwargs)
           ^^^^^^^^^^^^^^^^^^^^^^^^^^
  File "/home/airflow/.local/lib/python3.12/site-packages/airflow/models/baseoperator.py", line 417, in wrapper
    return func(self, *args, **kwargs)
           ^^^^^^^^^^^^^^^^^^^^^^^^^^^
  File "/home/airflow/.local/lib/python3.12/site-packages/airflow/providers/apache/kafka/operators/consume.py", line 130, in execute
    consumer = KafkaConsumerHook(topics=self.topics, kafka_config_id=self.kafka_config_id).get_consumer()
               ^^^^^^^^^^^^^^^^^^^^^^^^^^^^^^^^^^^^^^^^^^^^^^^^^^^^^^^^^^^^^^^^^^^^^^^^^^^^^^^^^^^^^^^^^^
  File "/home/airflow/.local/lib/python3.12/site-packages/airflow/providers/apache/kafka/hooks/consume.py", line 43, in get_consumer
    consumer = self.get_conn
               ^^^^^^^^^^^^^
  File "/usr/local/lib/python3.12/functools.py", line 993, in __get__
    val = self.func(instance)
          ^^^^^^^^^^^^^^^^^^^
  File "/home/airflow/.local/lib/python3.12/site-packages/airflow/providers/apache/kafka/hooks/base.py", line 61, in get_conn
    config = self.get_connection(self.kafka_config_id).extra_dejson
             ^^^^^^^^^^^^^^^^^^^^^^^^^^^^^^^^^^^^^^^^^
  File "/home/airflow/.local/lib/python3.12/site-packages/airflow/hooks/base.py", line 83, in get_connection
    conn = Connection.get_connection_from_secrets(conn_id)
           ^^^^^^^^^^^^^^^^^^^^^^^^^^^^^^^^^^^^^^^^^^^^^^^
  File "/home/airflow/.local/lib/python3.12/site-packages/airflow/models/connection.py", line 537, in get_connection_from_secrets
    raise AirflowNotFoundException(f"The conn_id `{conn_id}` isn't defined")
airflow.exceptions.AirflowNotFoundException: The conn_id `consume_kafka` isn't defined
[2024-12-05T06:40:56.105+0000] {taskinstance.py:1225} INFO - Marking task as FAILED. dag_id=kafka_read, task_id=consume_from_topic, run_id=scheduled__2024-12-04T00:00:00+00:00, execution_date=20241204T000000, start_date=20241205T064055, end_date=20241205T064056
[2024-12-05T06:40:56.116+0000] {taskinstance.py:340} INFO - ::group::Post task execution logs
[2024-12-05T06:40:56.116+0000] {standard_task_runner.py:124} ERROR - Failed to execute job 325 for task consume_from_topic (The conn_id `consume_kafka` isn't defined; 155)
Traceback (most recent call last):
  File "/home/airflow/.local/lib/python3.12/site-packages/airflow/task/task_runner/standard_task_runner.py", line 117, in _start_by_fork
    ret = args.func(args, dag=self.dag)
          ^^^^^^^^^^^^^^^^^^^^^^^^^^^^^
  File "/home/airflow/.local/lib/python3.12/site-packages/airflow/cli/cli_config.py", line 49, in command
    return func(*args, **kwargs)
           ^^^^^^^^^^^^^^^^^^^^^
  File "/home/airflow/.local/lib/python3.12/site-packages/airflow/utils/cli.py", line 116, in wrapper
    return f(*args, **kwargs)
           ^^^^^^^^^^^^^^^^^^
  File "/home/airflow/.local/lib/python3.12/site-packages/airflow/cli/commands/task_command.py", line 483, in task_run
    task_return_code = _run_task_by_selected_method(args, _dag, ti)
                       ^^^^^^^^^^^^^^^^^^^^^^^^^^^^^^^^^^^^^^^^^^^^
  File "/home/airflow/.local/lib/python3.12/site-packages/airflow/cli/commands/task_command.py", line 256, in _run_task_by_selected_method
    return _run_raw_task(args, ti)
           ^^^^^^^^^^^^^^^^^^^^^^^
  File "/home/airflow/.local/lib/python3.12/site-packages/airflow/cli/commands/task_command.py", line 341, in _run_raw_task
    return ti._run_raw_task(
           ^^^^^^^^^^^^^^^^^
  File "/home/airflow/.local/lib/python3.12/site-packages/airflow/utils/session.py", line 97, in wrapper
    return func(*args, session=session, **kwargs)
           ^^^^^^^^^^^^^^^^^^^^^^^^^^^^^^^^^^^^^^
  File "/home/airflow/.local/lib/python3.12/site-packages/airflow/models/taskinstance.py", line 3005, in _run_raw_task
    return _run_raw_task(
           ^^^^^^^^^^^^^^
  File "/home/airflow/.local/lib/python3.12/site-packages/airflow/models/taskinstance.py", line 273, in _run_raw_task
    TaskInstance._execute_task_with_callbacks(
  File "/home/airflow/.local/lib/python3.12/site-packages/airflow/models/taskinstance.py", line 3159, in _execute_task_with_callbacks
    result = self._execute_task(context, task_orig)
             ^^^^^^^^^^^^^^^^^^^^^^^^^^^^^^^^^^^^^^
  File "/home/airflow/.local/lib/python3.12/site-packages/airflow/models/taskinstance.py", line 3183, in _execute_task
    return _execute_task(self, context, task_orig)
           ^^^^^^^^^^^^^^^^^^^^^^^^^^^^^^^^^^^^^^^
  File "/home/airflow/.local/lib/python3.12/site-packages/airflow/models/taskinstance.py", line 767, in _execute_task
    result = _execute_callable(context=context, **execute_callable_kwargs)
             ^^^^^^^^^^^^^^^^^^^^^^^^^^^^^^^^^^^^^^^^^^^^^^^^^^^^^^^^^^^^^
  File "/home/airflow/.local/lib/python3.12/site-packages/airflow/models/taskinstance.py", line 733, in _execute_callable
    return ExecutionCallableRunner(
           ^^^^^^^^^^^^^^^^^^^^^^^^
  File "/home/airflow/.local/lib/python3.12/site-packages/airflow/utils/operator_helpers.py", line 252, in run
    return self.func(*args, **kwargs)
           ^^^^^^^^^^^^^^^^^^^^^^^^^^
  File "/home/airflow/.local/lib/python3.12/site-packages/airflow/models/baseoperator.py", line 417, in wrapper
    return func(self, *args, **kwargs)
           ^^^^^^^^^^^^^^^^^^^^^^^^^^^
  File "/home/airflow/.local/lib/python3.12/site-packages/airflow/providers/apache/kafka/operators/consume.py", line 130, in execute
    consumer = KafkaConsumerHook(topics=self.topics, kafka_config_id=self.kafka_config_id).get_consumer()
               ^^^^^^^^^^^^^^^^^^^^^^^^^^^^^^^^^^^^^^^^^^^^^^^^^^^^^^^^^^^^^^^^^^^^^^^^^^^^^^^^^^^^^^^^^^
  File "/home/airflow/.local/lib/python3.12/site-packages/airflow/providers/apache/kafka/hooks/consume.py", line 43, in get_consumer
    consumer = self.get_conn
               ^^^^^^^^^^^^^
  File "/usr/local/lib/python3.12/functools.py", line 993, in __get__
    val = self.func(instance)
          ^^^^^^^^^^^^^^^^^^^
  File "/home/airflow/.local/lib/python3.12/site-packages/airflow/providers/apache/kafka/hooks/base.py", line 61, in get_conn
    config = self.get_connection(self.kafka_config_id).extra_dejson
             ^^^^^^^^^^^^^^^^^^^^^^^^^^^^^^^^^^^^^^^^^
  File "/home/airflow/.local/lib/python3.12/site-packages/airflow/hooks/base.py", line 83, in get_connection
    conn = Connection.get_connection_from_secrets(conn_id)
           ^^^^^^^^^^^^^^^^^^^^^^^^^^^^^^^^^^^^^^^^^^^^^^^
  File "/home/airflow/.local/lib/python3.12/site-packages/airflow/models/connection.py", line 537, in get_connection_from_secrets
    raise AirflowNotFoundException(f"The conn_id `{conn_id}` isn't defined")
airflow.exceptions.AirflowNotFoundException: The conn_id `consume_kafka` isn't defined
[2024-12-05T06:40:56.137+0000] {local_task_job_runner.py:266} INFO - Task exited with return code 1
[2024-12-05T06:40:56.152+0000] {taskinstance.py:3895} INFO - 0 downstream tasks scheduled from follow-on schedule check
[2024-12-05T06:40:56.154+0000] {local_task_job_runner.py:245} INFO - ::endgroup::
