[2024-12-09T09:43:12.285+0000] {local_task_job_runner.py:123} INFO - ::group::Pre task execution logs
[2024-12-09T09:43:12.328+0000] {taskinstance.py:2613} INFO - Dependencies all met for dep_context=non-requeueable deps ti=<TaskInstance: s3_to_kafka_avro.read_from_minio manual__2024-12-09T09:38:05.443664+00:00 [queued]>
[2024-12-09T09:43:12.354+0000] {taskinstance.py:2613} INFO - Dependencies all met for dep_context=requeueable deps ti=<TaskInstance: s3_to_kafka_avro.read_from_minio manual__2024-12-09T09:38:05.443664+00:00 [queued]>
[2024-12-09T09:43:12.356+0000] {taskinstance.py:2866} INFO - Starting attempt 2 of 2
[2024-12-09T09:43:12.392+0000] {taskinstance.py:2889} INFO - Executing <Task(PythonOperator): read_from_minio> on 2024-12-09 09:38:05.443664+00:00
[2024-12-09T09:43:12.401+0000] {warnings.py:112} WARNING - /home/***/.local/lib/python3.12/site-packages/***/task/task_runner/standard_task_runner.py:70: DeprecationWarning: This process (pid=1765) is multi-threaded, use of fork() may lead to deadlocks in the child.
  pid = os.fork()

[2024-12-09T09:43:12.404+0000] {standard_task_runner.py:72} INFO - Started process 1766 to run task
[2024-12-09T09:43:12.405+0000] {standard_task_runner.py:104} INFO - Running: ['***', 'tasks', 'run', 's3_to_kafka_avro', 'read_from_minio', 'manual__2024-12-09T09:38:05.443664+00:00', '--job-id', '47', '--raw', '--subdir', 'DAGS_FOLDER/dag3_s3_kafka.py', '--cfg-path', '/tmp/tmpvk49z_i6']
[2024-12-09T09:43:12.410+0000] {standard_task_runner.py:105} INFO - Job 47: Subtask read_from_minio
[2024-12-09T09:43:12.497+0000] {task_command.py:467} INFO - Running <TaskInstance: s3_to_kafka_avro.read_from_minio manual__2024-12-09T09:38:05.443664+00:00 [running]> on host c23cf8b5bd6f
[2024-12-09T09:43:12.686+0000] {taskinstance.py:3132} INFO - Exporting env vars: AIRFLOW_CTX_DAG_OWNER='***' AIRFLOW_CTX_DAG_ID='s3_to_kafka_avro' AIRFLOW_CTX_TASK_ID='read_from_minio' AIRFLOW_CTX_EXECUTION_DATE='2024-12-09T09:38:05.443664+00:00' AIRFLOW_CTX_TRY_NUMBER='2' AIRFLOW_CTX_DAG_RUN_ID='manual__2024-12-09T09:38:05.443664+00:00'
[2024-12-09T09:43:12.690+0000] {taskinstance.py:731} INFO - ::endgroup::
[2024-12-09T09:43:13.027+0000] {logging_mixin.py:190} INFO - Подключение успешно. Найдено 7 бакетов: ['levs-test', 'mybucket', 'reciept-bucket', 'spark', 'test-bucket', 'travel', 'users-add']
[2024-12-09T09:43:13.131+0000] {logging_mixin.py:190} INFO - Содержимое бакета reciept-bucket:
[2024-12-09T09:43:13.132+0000] {logging_mixin.py:190} INFO - <class 'dict'>
[2024-12-09T09:43:13.145+0000] {taskinstance.py:3311} ERROR - Task failed with exception
Traceback (most recent call last):
  File "/home/airflow/.local/lib/python3.12/site-packages/airflow/models/taskinstance.py", line 767, in _execute_task
    result = _execute_callable(context=context, **execute_callable_kwargs)
             ^^^^^^^^^^^^^^^^^^^^^^^^^^^^^^^^^^^^^^^^^^^^^^^^^^^^^^^^^^^^^
  File "/home/airflow/.local/lib/python3.12/site-packages/airflow/models/taskinstance.py", line 733, in _execute_callable
    return ExecutionCallableRunner(
           ^^^^^^^^^^^^^^^^^^^^^^^^
  File "/home/airflow/.local/lib/python3.12/site-packages/airflow/utils/operator_helpers.py", line 252, in run
    return self.func(*args, **kwargs)
           ^^^^^^^^^^^^^^^^^^^^^^^^^^
  File "/home/airflow/.local/lib/python3.12/site-packages/airflow/models/baseoperator.py", line 417, in wrapper
    return func(self, *args, **kwargs)
           ^^^^^^^^^^^^^^^^^^^^^^^^^^^
  File "/home/airflow/.local/lib/python3.12/site-packages/airflow/operators/python.py", line 238, in execute
    return_value = self.execute_callable()
                   ^^^^^^^^^^^^^^^^^^^^^^^
  File "/home/airflow/.local/lib/python3.12/site-packages/airflow/operators/python.py", line 256, in execute_callable
    return runner.run(*self.op_args, **self.op_kwargs)
           ^^^^^^^^^^^^^^^^^^^^^^^^^^^^^^^^^^^^^^^^^^^
  File "/home/airflow/.local/lib/python3.12/site-packages/airflow/utils/operator_helpers.py", line 252, in run
    return self.func(*args, **kwargs)
           ^^^^^^^^^^^^^^^^^^^^^^^^^^
  File "/opt/airflow/dags/dag3_s3_kafka.py", line 82, in read_from_minio
    send_to_kafka(obj)
  File "/opt/airflow/dags/dag3_s3_kafka.py", line 61, in send_to_kafka
    kafka_conn_id = Variable.get(KAFKA_URL, deserialize_json=True)
                    ^^^^^^^^^^^^^^^^^^^^^^^^^^^^^^^^^^^^^^^^^^^^^^
  File "/home/airflow/.local/lib/python3.12/site-packages/airflow/models/variable.py", line 145, in get
    raise KeyError(f"Variable {key} does not exist")
KeyError: 'Variable 172.30.181.198:9092 does not exist'
[2024-12-09T09:43:13.167+0000] {taskinstance.py:1225} INFO - Marking task as FAILED. dag_id=s3_to_kafka_avro, task_id=read_from_minio, run_id=manual__2024-12-09T09:38:05.443664+00:00, execution_date=20241209T093805, start_date=20241209T094312, end_date=20241209T094313
[2024-12-09T09:43:13.190+0000] {taskinstance.py:340} INFO - ::group::Post task execution logs
[2024-12-09T09:43:13.192+0000] {standard_task_runner.py:124} ERROR - Failed to execute job 47 for task read_from_minio ('Variable 172.30.181.198:9092 does not exist'; 1766)
Traceback (most recent call last):
  File "/home/airflow/.local/lib/python3.12/site-packages/airflow/task/task_runner/standard_task_runner.py", line 117, in _start_by_fork
    ret = args.func(args, dag=self.dag)
          ^^^^^^^^^^^^^^^^^^^^^^^^^^^^^
  File "/home/airflow/.local/lib/python3.12/site-packages/airflow/cli/cli_config.py", line 49, in command
    return func(*args, **kwargs)
           ^^^^^^^^^^^^^^^^^^^^^
  File "/home/airflow/.local/lib/python3.12/site-packages/airflow/utils/cli.py", line 116, in wrapper
    return f(*args, **kwargs)
           ^^^^^^^^^^^^^^^^^^
  File "/home/airflow/.local/lib/python3.12/site-packages/airflow/cli/commands/task_command.py", line 483, in task_run
    task_return_code = _run_task_by_selected_method(args, _dag, ti)
                       ^^^^^^^^^^^^^^^^^^^^^^^^^^^^^^^^^^^^^^^^^^^^
  File "/home/airflow/.local/lib/python3.12/site-packages/airflow/cli/commands/task_command.py", line 256, in _run_task_by_selected_method
    return _run_raw_task(args, ti)
           ^^^^^^^^^^^^^^^^^^^^^^^
  File "/home/airflow/.local/lib/python3.12/site-packages/airflow/cli/commands/task_command.py", line 341, in _run_raw_task
    return ti._run_raw_task(
           ^^^^^^^^^^^^^^^^^
  File "/home/airflow/.local/lib/python3.12/site-packages/airflow/utils/session.py", line 97, in wrapper
    return func(*args, session=session, **kwargs)
           ^^^^^^^^^^^^^^^^^^^^^^^^^^^^^^^^^^^^^^
  File "/home/airflow/.local/lib/python3.12/site-packages/airflow/models/taskinstance.py", line 3005, in _run_raw_task
    return _run_raw_task(
           ^^^^^^^^^^^^^^
  File "/home/airflow/.local/lib/python3.12/site-packages/airflow/models/taskinstance.py", line 273, in _run_raw_task
    TaskInstance._execute_task_with_callbacks(
  File "/home/airflow/.local/lib/python3.12/site-packages/airflow/models/taskinstance.py", line 3159, in _execute_task_with_callbacks
    result = self._execute_task(context, task_orig)
             ^^^^^^^^^^^^^^^^^^^^^^^^^^^^^^^^^^^^^^
  File "/home/airflow/.local/lib/python3.12/site-packages/airflow/models/taskinstance.py", line 3183, in _execute_task
    return _execute_task(self, context, task_orig)
           ^^^^^^^^^^^^^^^^^^^^^^^^^^^^^^^^^^^^^^^
  File "/home/airflow/.local/lib/python3.12/site-packages/airflow/models/taskinstance.py", line 767, in _execute_task
    result = _execute_callable(context=context, **execute_callable_kwargs)
             ^^^^^^^^^^^^^^^^^^^^^^^^^^^^^^^^^^^^^^^^^^^^^^^^^^^^^^^^^^^^^
  File "/home/airflow/.local/lib/python3.12/site-packages/airflow/models/taskinstance.py", line 733, in _execute_callable
    return ExecutionCallableRunner(
           ^^^^^^^^^^^^^^^^^^^^^^^^
  File "/home/airflow/.local/lib/python3.12/site-packages/airflow/utils/operator_helpers.py", line 252, in run
    return self.func(*args, **kwargs)
           ^^^^^^^^^^^^^^^^^^^^^^^^^^
  File "/home/airflow/.local/lib/python3.12/site-packages/airflow/models/baseoperator.py", line 417, in wrapper
    return func(self, *args, **kwargs)
           ^^^^^^^^^^^^^^^^^^^^^^^^^^^
  File "/home/airflow/.local/lib/python3.12/site-packages/airflow/operators/python.py", line 238, in execute
    return_value = self.execute_callable()
                   ^^^^^^^^^^^^^^^^^^^^^^^
  File "/home/airflow/.local/lib/python3.12/site-packages/airflow/operators/python.py", line 256, in execute_callable
    return runner.run(*self.op_args, **self.op_kwargs)
           ^^^^^^^^^^^^^^^^^^^^^^^^^^^^^^^^^^^^^^^^^^^
  File "/home/airflow/.local/lib/python3.12/site-packages/airflow/utils/operator_helpers.py", line 252, in run
    return self.func(*args, **kwargs)
           ^^^^^^^^^^^^^^^^^^^^^^^^^^
  File "/opt/airflow/dags/dag3_s3_kafka.py", line 82, in read_from_minio
    send_to_kafka(obj)
  File "/opt/airflow/dags/dag3_s3_kafka.py", line 61, in send_to_kafka
    kafka_conn_id = Variable.get(KAFKA_URL, deserialize_json=True)
                    ^^^^^^^^^^^^^^^^^^^^^^^^^^^^^^^^^^^^^^^^^^^^^^
  File "/home/airflow/.local/lib/python3.12/site-packages/airflow/models/variable.py", line 145, in get
    raise KeyError(f"Variable {key} does not exist")
KeyError: 'Variable 172.30.181.198:9092 does not exist'
[2024-12-09T09:43:13.231+0000] {local_task_job_runner.py:266} INFO - Task exited with return code 1
[2024-12-09T09:43:13.258+0000] {taskinstance.py:3895} INFO - 0 downstream tasks scheduled from follow-on schedule check
[2024-12-09T09:43:13.262+0000] {local_task_job_runner.py:245} INFO - ::endgroup::
