[2024-12-06T06:25:51.497+0000] {local_task_job_runner.py:123} INFO - ::group::Pre task execution logs
[2024-12-06T06:25:51.520+0000] {taskinstance.py:2613} INFO - Dependencies all met for dep_context=non-requeueable deps ti=<TaskInstance: dag1.fetch_mongo_data scheduled__2024-12-05T00:00:00+00:00 [queued]>
[2024-12-06T06:25:51.532+0000] {taskinstance.py:2613} INFO - Dependencies all met for dep_context=requeueable deps ti=<TaskInstance: dag1.fetch_mongo_data scheduled__2024-12-05T00:00:00+00:00 [queued]>
[2024-12-06T06:25:51.533+0000] {taskinstance.py:2866} INFO - Starting attempt 1 of 2
[2024-12-06T06:25:51.550+0000] {taskinstance.py:2889} INFO - Executing <Task(PythonOperator): fetch_mongo_data> on 2024-12-05 00:00:00+00:00
[2024-12-06T06:25:51.555+0000] {warnings.py:112} WARNING - /home/***/.local/lib/python3.12/site-packages/***/task/task_runner/standard_task_runner.py:70: DeprecationWarning: This process (pid=78) is multi-threaded, use of fork() may lead to deadlocks in the child.
  pid = os.fork()

[2024-12-06T06:25:51.558+0000] {standard_task_runner.py:72} INFO - Started process 81 to run task
[2024-12-06T06:25:51.558+0000] {standard_task_runner.py:104} INFO - Running: ['***', 'tasks', 'run', 'dag1', 'fetch_mongo_data', 'scheduled__2024-12-05T00:00:00+00:00', '--job-id', '412', '--raw', '--subdir', 'DAGS_FOLDER/dag1_producer_mongo.py', '--cfg-path', '/tmp/tmpe0kn35oq']
[2024-12-06T06:25:51.561+0000] {standard_task_runner.py:105} INFO - Job 412: Subtask fetch_mongo_data
[2024-12-06T06:25:51.611+0000] {task_command.py:467} INFO - Running <TaskInstance: dag1.fetch_mongo_data scheduled__2024-12-05T00:00:00+00:00 [running]> on host bc436253e42c
[2024-12-06T06:25:51.706+0000] {taskinstance.py:3132} INFO - Exporting env vars: AIRFLOW_CTX_DAG_OWNER='***' AIRFLOW_CTX_DAG_ID='dag1' AIRFLOW_CTX_TASK_ID='fetch_mongo_data' AIRFLOW_CTX_EXECUTION_DATE='2024-12-05T00:00:00+00:00' AIRFLOW_CTX_TRY_NUMBER='1' AIRFLOW_CTX_DAG_RUN_ID='scheduled__2024-12-05T00:00:00+00:00'
[2024-12-06T06:25:51.707+0000] {taskinstance.py:731} INFO - ::endgroup::
[2024-12-06T06:26:13.499+0000] {taskinstance.py:3311} ERROR - Task failed with exception
Traceback (most recent call last):
  File "/home/airflow/.local/lib/python3.12/site-packages/airflow/models/taskinstance.py", line 767, in _execute_task
    result = _execute_callable(context=context, **execute_callable_kwargs)
             ^^^^^^^^^^^^^^^^^^^^^^^^^^^^^^^^^^^^^^^^^^^^^^^^^^^^^^^^^^^^^
  File "/home/airflow/.local/lib/python3.12/site-packages/airflow/models/taskinstance.py", line 733, in _execute_callable
    return ExecutionCallableRunner(
           ^^^^^^^^^^^^^^^^^^^^^^^^
  File "/home/airflow/.local/lib/python3.12/site-packages/airflow/utils/operator_helpers.py", line 252, in run
    return self.func(*args, **kwargs)
           ^^^^^^^^^^^^^^^^^^^^^^^^^^
  File "/home/airflow/.local/lib/python3.12/site-packages/airflow/models/baseoperator.py", line 417, in wrapper
    return func(self, *args, **kwargs)
           ^^^^^^^^^^^^^^^^^^^^^^^^^^^
  File "/home/airflow/.local/lib/python3.12/site-packages/airflow/operators/python.py", line 238, in execute
    return_value = self.execute_callable()
                   ^^^^^^^^^^^^^^^^^^^^^^^
  File "/home/airflow/.local/lib/python3.12/site-packages/airflow/operators/python.py", line 256, in execute_callable
    return runner.run(*self.op_args, **self.op_kwargs)
           ^^^^^^^^^^^^^^^^^^^^^^^^^^^^^^^^^^^^^^^^^^^
  File "/home/airflow/.local/lib/python3.12/site-packages/airflow/utils/operator_helpers.py", line 252, in run
    return self.func(*args, **kwargs)
           ^^^^^^^^^^^^^^^^^^^^^^^^^^
  File "/opt/airflow/dags/dag1_producer_mongo.py", line 22, in fetch_data_from_mongo
    client = MongoClient(
             ^^^^^^^^^^^^
  File "/home/airflow/.local/lib/python3.12/site-packages/pymongo/synchronous/mongo_client.py", line 780, in __init__
    res = uri_parser.parse_uri(
          ^^^^^^^^^^^^^^^^^^^^^
  File "/home/airflow/.local/lib/python3.12/site-packages/pymongo/uri_parser.py", line 558, in parse_uri
    nodes = dns_resolver.get_hosts()
            ^^^^^^^^^^^^^^^^^^^^^^^^
  File "/home/airflow/.local/lib/python3.12/site-packages/pymongo/srv_resolver.py", line 140, in get_hosts
    _, nodes = self._get_srv_response_and_hosts(True)
               ^^^^^^^^^^^^^^^^^^^^^^^^^^^^^^^^^^^^^^
  File "/home/airflow/.local/lib/python3.12/site-packages/pymongo/srv_resolver.py", line 120, in _get_srv_response_and_hosts
    results = self._resolve_uri(encapsulate_errors)
              ^^^^^^^^^^^^^^^^^^^^^^^^^^^^^^^^^^^^^
  File "/home/airflow/.local/lib/python3.12/site-packages/pymongo/srv_resolver.py", line 114, in _resolve_uri
    raise ConfigurationError(str(exc)) from None
pymongo.errors.ConfigurationError: The resolution lifetime expired after 21.496 seconds: Server Do53:127.0.0.11@53 answered The DNS operation timed out.; Server Do53:127.0.0.11@53 answered The DNS operation timed out.; Server Do53:127.0.0.11@53 answered The DNS operation timed out.; Server Do53:127.0.0.11@53 answered The DNS operation timed out.; Server Do53:127.0.0.11@53 answered The DNS operation timed out.; Server Do53:127.0.0.11@53 answered The DNS operation timed out.; Server Do53:127.0.0.11@53 answered The DNS operation timed out.
[2024-12-06T06:26:13.526+0000] {taskinstance.py:1225} INFO - Marking task as UP_FOR_RETRY. dag_id=dag1, task_id=fetch_mongo_data, run_id=scheduled__2024-12-05T00:00:00+00:00, execution_date=20241205T000000, start_date=20241206T062551, end_date=20241206T062613
[2024-12-06T06:26:13.550+0000] {taskinstance.py:340} INFO - ::group::Post task execution logs
[2024-12-06T06:26:13.551+0000] {standard_task_runner.py:124} ERROR - Failed to execute job 412 for task fetch_mongo_data (The resolution lifetime expired after 21.496 seconds: Server Do53:127.0.0.11@53 answered The DNS operation timed out.; Server Do53:127.0.0.11@53 answered The DNS operation timed out.; Server Do53:127.0.0.11@53 answered The DNS operation timed out.; Server Do53:127.0.0.11@53 answered The DNS operation timed out.; Server Do53:127.0.0.11@53 answered The DNS operation timed out.; Server Do53:127.0.0.11@53 answered The DNS operation timed out.; Server Do53:127.0.0.11@53 answered The DNS operation timed out.; 81)
Traceback (most recent call last):
  File "/home/airflow/.local/lib/python3.12/site-packages/airflow/task/task_runner/standard_task_runner.py", line 117, in _start_by_fork
    ret = args.func(args, dag=self.dag)
          ^^^^^^^^^^^^^^^^^^^^^^^^^^^^^
  File "/home/airflow/.local/lib/python3.12/site-packages/airflow/cli/cli_config.py", line 49, in command
    return func(*args, **kwargs)
           ^^^^^^^^^^^^^^^^^^^^^
  File "/home/airflow/.local/lib/python3.12/site-packages/airflow/utils/cli.py", line 116, in wrapper
    return f(*args, **kwargs)
           ^^^^^^^^^^^^^^^^^^
  File "/home/airflow/.local/lib/python3.12/site-packages/airflow/cli/commands/task_command.py", line 483, in task_run
    task_return_code = _run_task_by_selected_method(args, _dag, ti)
                       ^^^^^^^^^^^^^^^^^^^^^^^^^^^^^^^^^^^^^^^^^^^^
  File "/home/airflow/.local/lib/python3.12/site-packages/airflow/cli/commands/task_command.py", line 256, in _run_task_by_selected_method
    return _run_raw_task(args, ti)
           ^^^^^^^^^^^^^^^^^^^^^^^
  File "/home/airflow/.local/lib/python3.12/site-packages/airflow/cli/commands/task_command.py", line 341, in _run_raw_task
    return ti._run_raw_task(
           ^^^^^^^^^^^^^^^^^
  File "/home/airflow/.local/lib/python3.12/site-packages/airflow/utils/session.py", line 97, in wrapper
    return func(*args, session=session, **kwargs)
           ^^^^^^^^^^^^^^^^^^^^^^^^^^^^^^^^^^^^^^
  File "/home/airflow/.local/lib/python3.12/site-packages/airflow/models/taskinstance.py", line 3005, in _run_raw_task
    return _run_raw_task(
           ^^^^^^^^^^^^^^
  File "/home/airflow/.local/lib/python3.12/site-packages/airflow/models/taskinstance.py", line 273, in _run_raw_task
    TaskInstance._execute_task_with_callbacks(
  File "/home/airflow/.local/lib/python3.12/site-packages/airflow/models/taskinstance.py", line 3159, in _execute_task_with_callbacks
    result = self._execute_task(context, task_orig)
             ^^^^^^^^^^^^^^^^^^^^^^^^^^^^^^^^^^^^^^
  File "/home/airflow/.local/lib/python3.12/site-packages/airflow/models/taskinstance.py", line 3183, in _execute_task
    return _execute_task(self, context, task_orig)
           ^^^^^^^^^^^^^^^^^^^^^^^^^^^^^^^^^^^^^^^
  File "/home/airflow/.local/lib/python3.12/site-packages/airflow/models/taskinstance.py", line 767, in _execute_task
    result = _execute_callable(context=context, **execute_callable_kwargs)
             ^^^^^^^^^^^^^^^^^^^^^^^^^^^^^^^^^^^^^^^^^^^^^^^^^^^^^^^^^^^^^
  File "/home/airflow/.local/lib/python3.12/site-packages/airflow/models/taskinstance.py", line 733, in _execute_callable
    return ExecutionCallableRunner(
           ^^^^^^^^^^^^^^^^^^^^^^^^
  File "/home/airflow/.local/lib/python3.12/site-packages/airflow/utils/operator_helpers.py", line 252, in run
    return self.func(*args, **kwargs)
           ^^^^^^^^^^^^^^^^^^^^^^^^^^
  File "/home/airflow/.local/lib/python3.12/site-packages/airflow/models/baseoperator.py", line 417, in wrapper
    return func(self, *args, **kwargs)
           ^^^^^^^^^^^^^^^^^^^^^^^^^^^
  File "/home/airflow/.local/lib/python3.12/site-packages/airflow/operators/python.py", line 238, in execute
    return_value = self.execute_callable()
                   ^^^^^^^^^^^^^^^^^^^^^^^
  File "/home/airflow/.local/lib/python3.12/site-packages/airflow/operators/python.py", line 256, in execute_callable
    return runner.run(*self.op_args, **self.op_kwargs)
           ^^^^^^^^^^^^^^^^^^^^^^^^^^^^^^^^^^^^^^^^^^^
  File "/home/airflow/.local/lib/python3.12/site-packages/airflow/utils/operator_helpers.py", line 252, in run
    return self.func(*args, **kwargs)
           ^^^^^^^^^^^^^^^^^^^^^^^^^^
  File "/opt/airflow/dags/dag1_producer_mongo.py", line 22, in fetch_data_from_mongo
    client = MongoClient(
             ^^^^^^^^^^^^
  File "/home/airflow/.local/lib/python3.12/site-packages/pymongo/synchronous/mongo_client.py", line 780, in __init__
    res = uri_parser.parse_uri(
          ^^^^^^^^^^^^^^^^^^^^^
  File "/home/airflow/.local/lib/python3.12/site-packages/pymongo/uri_parser.py", line 558, in parse_uri
    nodes = dns_resolver.get_hosts()
            ^^^^^^^^^^^^^^^^^^^^^^^^
  File "/home/airflow/.local/lib/python3.12/site-packages/pymongo/srv_resolver.py", line 140, in get_hosts
    _, nodes = self._get_srv_response_and_hosts(True)
               ^^^^^^^^^^^^^^^^^^^^^^^^^^^^^^^^^^^^^^
  File "/home/airflow/.local/lib/python3.12/site-packages/pymongo/srv_resolver.py", line 120, in _get_srv_response_and_hosts
    results = self._resolve_uri(encapsulate_errors)
              ^^^^^^^^^^^^^^^^^^^^^^^^^^^^^^^^^^^^^
  File "/home/airflow/.local/lib/python3.12/site-packages/pymongo/srv_resolver.py", line 114, in _resolve_uri
    raise ConfigurationError(str(exc)) from None
pymongo.errors.ConfigurationError: The resolution lifetime expired after 21.496 seconds: Server Do53:127.0.0.11@53 answered The DNS operation timed out.; Server Do53:127.0.0.11@53 answered The DNS operation timed out.; Server Do53:127.0.0.11@53 answered The DNS operation timed out.; Server Do53:127.0.0.11@53 answered The DNS operation timed out.; Server Do53:127.0.0.11@53 answered The DNS operation timed out.; Server Do53:127.0.0.11@53 answered The DNS operation timed out.; Server Do53:127.0.0.11@53 answered The DNS operation timed out.
[2024-12-06T06:26:13.586+0000] {local_task_job_runner.py:266} INFO - Task exited with return code 1
[2024-12-06T06:26:13.615+0000] {taskinstance.py:3895} INFO - 0 downstream tasks scheduled from follow-on schedule check
[2024-12-06T06:26:13.617+0000] {local_task_job_runner.py:245} INFO - ::endgroup::
